<?xml version="1.0" encoding="utf-8"?>
<!-- This URDF was automatically created by SolidWorks to URDF Exporter! Originally created by Stephen Brawner (brawner@gmail.com) 
     Commit Version: 1.6.0-4-g7f85cfe  Build Version: 1.6.7995.38578
     For more information, please see http://wiki.ros.org/sw_urdf_exporter -->
<robot
  name="rlr_urdf">
  <link name="world"/>
  <joint name="base_joint" type="fixed">
    <parent link="world"/>
    <child link="base_link"/>
    <origin rpy="0 0 0" xyz="0.0 0.0 0.0"/>
  </joint>
  <link
    name="base_link">
    <inertial>
      <origin
        xyz="0.0034218 1.349E-17 0.11552"
        rpy="0 0 0" />
      <mass
        value="1.1848" />
      <inertia
        ixx="0.003116"
        ixy="-5.7826E-21"
        ixz="4.7002E-09"
        iyy="0.003136"
        iyz="-1.6352E-19"
        izz="0.00060234" />
    </inertial>
    <visual>
      <origin
        xyz="0 0 0"
        rpy="0 0 0" />
      <geometry>
        <mesh
          filename="package://meshes/base_link.STL" />
      </geometry>
      <material
        name="">
        <color
          rgba="0.89804 0.91765 0.92941 1" />
      </material>
    </visual>
    <collision>
      <origin
        xyz="0 0 0"
        rpy="0 0 0" />
      <geometry>
        <mesh
          filename="package://meshes/base_link.STL" />
      </geometry>
    </collision>
  </link>
  <link
    name="link1">
    <inertial>
      <origin
        xyz="-0.0047028 0.020543 -1.5632E-11"
        rpy="0 0 0" />
      <mass
        value="0.27755" />
      <inertia
        ixx="8.2467E-05"
        ixy="-2.3543E-06"
        ixz="-4.3357E-15"
        iyy="7.4118E-05"
        iyz="4.7567E-15"
        izz="4.5494E-05" />
    </inertial>
    <visual>
      <origin
        xyz="0 0 0"
        rpy="0 0 0" />
      <geometry>
        <mesh
          filename="package://meshes/link1.STL" />
      </geometry>
      <material
        name="">
        <color
          rgba="1 1 1 1" />
      </material>
    </visual>
    <collision>
      <origin
        xyz="0 0 0"
        rpy="0 0 0" />
      <geometry>
        <mesh
          filename="package://meshes/link1.STL" />
      </geometry>
    </collision>
  </link>
  <joint
    name="joint1"
    type="continuous">
    <origin
      xyz="0 0 0.213"
      rpy="1.5708 0 1.5708" />
    <parent
      link="base_link" />
    <child
      link="link1" />
    <axis
      xyz="0 1 0" />
    <limit
      lower="-3.14"
      upper="3.14"
      effort="0.07"
      velocity="46" />
  </joint>
  <link
    name="link2">
    <inertial>
      <origin
        xyz="3.3578E-06 -0.046206 -0.079149"
        rpy="0 0 0" />
      <mass
        value="0.072015" />
      <inertia
        ixx="6.521E-05"
        ixy="-3.0229E-09"
        ixz="-1.9355E-12"
        iyy="4.5617E-05"
        iyz="1.418E-14"
        izz="2.1907E-05" />
    </inertial>
    <visual>
      <origin
        xyz="0 0 0"
        rpy="0 0 0" />
      <geometry>
        <mesh
          filename="package://meshes/link2.STL" />
      </geometry>
      <material
        name="">
        <color
          rgba="0.89804 0.91765 0.92941 1" />
      </material>
    </visual>
    <collision>
      <origin
        xyz="0 0 0"
        rpy="0 0 0" />
      <geometry>
        <mesh
          filename="package://meshes/link2.STL" />
      </geometry>
    </collision>
  </link>
  <joint
    name="joint2"
    type="continuous">
    <origin
      xyz="0 0.025 0"
      rpy="0 1.5708 0" />
    <parent
      link="link1" />
    <child
      link="link2" />
    <axis
      xyz="0 0 1" />
  </joint>
</robot>
