<?xml version="1.0" encoding="utf-8"?>
<!-- This URDF was automatically created by SolidWorks to URDF Exporter! Originally created by Stephen Brawner (brawner@gmail.com) 
     Commit Version: 1.6.0-4-g7f85cfe  Build Version: 1.6.7995.38578
     For more information, please see http://wiki.ros.org/sw_urdf_exporter -->
<robot
  name="rlr_urdf">
  <link name="world"/>
  <joint name="base_joint" type="fixed">
    <parent link="world"/>
    <child link="base_link"/>
    <origin rpy="0 0 0" xyz="0.0 0.0 0.0"/>
  </joint>
  
  <link
    name="base_link">
    <inertial>
      <origin
        xyz="-1.2854E-06 0.1135 -8.347E-08"
        rpy="0 0 0" />
      <mass
        value="1.1686" />
      <inertia
        ixx="0.0030181"
        ixy="-7.6146E-21"
        ixz="1.0935E-20"
        iyy="0.00034337"
        iyz="3.1715E-09"
        izz="0.0030183" />
    </inertial>
    <visual>
      <origin
        xyz="0 0 0"
        rpy="0 0 0" />
      <geometry>
        <mesh
          filename="package://urdf and meshes/without weight/meshes/base_link.STL" />
      </geometry>
      <material
        name="">
        <color
          rgba="0.89804 0.91765 0.92941 1" />
      </material>
    </visual>
    <collision>
      <origin
        xyz="0 0 0"
        rpy="0 0 0" />
      <geometry>
        <mesh
          filename="package://urdf and meshes/without weight/meshes/base_link.STL" />
      </geometry>
    </collision>
  </link>
  <link
    name="link1">
    <inertial>
      <origin
        xyz="-0.0050566 0.020502 9.4512E-12"
        rpy="0 0 0" />
      <mass
        value="0.27518" />
      <inertia
        ixx="8.1044E-05"
        ixy="-9.6978E-07"
        ixz="-7.1922E-15"
        iyy="7.1666E-05"
        iyz="-1.1662E-14"
        izz="4.1838E-05" />
    </inertial>
    <visual>
      <origin
        xyz="0 0 0"
        rpy="0 0 0" />
      <geometry>
        <mesh
          filename="package://urdf and meshes/without weight/meshes/link1.STL" />
      </geometry>
      <material
        name="">
        <color
          rgba="1 1 1 1" />
      </material>
    </visual>
    <collision>
      <origin
        xyz="0 0 0"
        rpy="0 0 0" />
      <geometry>
        <mesh
          filename="package://urdf and meshes/without weight/meshes/link1.STL" />
      </geometry>
    </collision>
  </link>
  <joint
    name="joint1"
    type="revolute">
    <origin
      xyz="0 0 0.213"
      rpy="1.5708 0 1.5708" />
    <parent
      link="base_link" />
    <child
      link="link1" />
    <axis
      xyz="0 1 0" >
    </axis>
    <limit
      lower="-4.71"
      upper="4.71"
      effort="0.07"
      velocity="46" />
    <dynamics damping="0.0"
            friction="0.001"/>
  </joint>
  <link
    name="link2">
    <inertial>
      <origin
        xyz="3.7251E-06 -0.04004 -0.07654"
        rpy="0 0 0" />
      <mass
        value="0.064915" />
      <inertia
        ixx="0.00010421"
        ixy="-3.0229E-09"
        ixz="-1.9355E-12"
        iyy="4.4236E-05"
        iyz="1.418E-14"
        izz="6.0908E-05" />
    </inertial>
    <visual>
      <origin
        xyz="0 0 0"
        rpy="0 0 0" />
      <geometry>
        <mesh
          filename="package://urdf and meshes/without weight/meshes/link2.STL" />
      </geometry>
      <material
        name="">
        <color
          rgba="0.89804 0.91765 0.92941 1" />
      </material>
    </visual>
    <collision>
      <origin
        xyz="0 0 0"
        rpy="0 0 0" />
      <geometry>
        <mesh
          filename="package://urdf and meshes/without weight/meshes/link2.STL" />
      </geometry>
    </collision>
  </link>
  <joint
    name="joint2"
    type="continuous">
    <origin
      xyz="0 0.025 0"
      rpy="0 1.5708 0" />
    <parent
      link="link1" />
    <child
      link="link2" />
    <axis
      xyz="0 0 1">
    </axis>
    <dynamics damping="0.0"
              friction="0.001"/>
  </joint>
</robot>
